Traceback (most recent call last):
  File "/home/user/bot-api-django/.venv/lib/python3.11/site-packages/urllib3/connection.py", line 196, in _new_conn
    sock = connection.create_connection(
           ^^^^^^^^^^^^^^^^^^^^^^^^^^^^^
  File "/home/user/bot-api-django/.venv/lib/python3.11/site-packages/urllib3/util/connection.py", line 85, in create_connection
    raise err
  File "/home/user/bot-api-django/.venv/lib/python3.11/site-packages/urllib3/util/connection.py", line 73, in create_connection
    sock.connect(sa)
ConnectionRefusedError: [Errno 111] Connection refused

The above exception was the direct cause of the following exception:

Traceback (most recent call last):
  File "/home/user/bot-api-django/.venv/lib/python3.11/site-packages/urllib3/connectionpool.py", line 789, in urlopen
    response = self._make_request(
               ^^^^^^^^^^^^^^^^^^^
  File "/home/user/bot-api-django/.venv/lib/python3.11/site-packages/urllib3/connectionpool.py", line 495, in _make_request
    conn.request(
  File "/home/user/bot-api-django/.venv/lib/python3.11/site-packages/urllib3/connection.py", line 398, in request
    self.endheaders()
  File "/usr/lib/python3.11/http/client.py", line 1293, in endheaders
    self._send_output(message_body, encode_chunked=encode_chunked)
  File "/usr/lib/python3.11/http/client.py", line 1052, in _send_output
    self.send(msg)
  File "/usr/lib/python3.11/http/client.py", line 990, in send
    self.connect()
  File "/home/user/bot-api-django/.venv/lib/python3.11/site-packages/urllib3/connection.py", line 236, in connect
    self.sock = self._new_conn()
                ^^^^^^^^^^^^^^^^
  File "/home/user/bot-api-django/.venv/lib/python3.11/site-packages/urllib3/connection.py", line 211, in _new_conn
    raise NewConnectionError(
urllib3.exceptions.NewConnectionError: <urllib3.connection.HTTPConnection object at 0x7818a6287910>: Failed to establish a new connection: [Errno 111] Connection refused

The above exception was the direct cause of the following exception:

Traceback (most recent call last):
  File "/home/user/bot-api-django/.venv/lib/python3.11/site-packages/requests/adapters.py", line 667, in send
    resp = conn.urlopen(
           ^^^^^^^^^^^^^
  File "/home/user/bot-api-django/.venv/lib/python3.11/site-packages/urllib3/connectionpool.py", line 843, in urlopen
    retries = retries.increment(
              ^^^^^^^^^^^^^^^^^^
  File "/home/user/bot-api-django/.venv/lib/python3.11/site-packages/urllib3/util/retry.py", line 519, in increment
    raise MaxRetryError(_pool, url, reason) from reason  # type: ignore[arg-type]
    ^^^^^^^^^^^^^^^^^^^^^^^^^^^^^^^^^^^^^^^^^^^^^^^^^^^
urllib3.exceptions.MaxRetryError: HTTPConnectionPool(host='127.0.0.1', port=8000): Max retries exceeded with url: /category/ (Caused by NewConnectionError('<urllib3.connection.HTTPConnection object at 0x7818a6287910>: Failed to establish a new connection: [Errno 111] Connection refused'))

During handling of the above exception, another exception occurred:

Traceback (most recent call last):
  File "/home/user/bot-api-django/app.py", line 5, in <module>
    import middlewares, filters, handlers
  File "/home/user/bot-api-django/handlers/__init__.py", line 2, in <module>
    from . import users
  File "/home/user/bot-api-django/handlers/users/__init__.py", line 1, in <module>
    from . import help
  File "/home/user/bot-api-django/handlers/users/help.py", line 4, in <module>
    from keyboards.default.newkeyboards import menu
  File "/home/user/bot-api-django/keyboards/__init__.py", line 1, in <module>
    from . import default
  File "/home/user/bot-api-django/keyboards/default/__init__.py", line 2, in <module>
    from . import orderkeyboards
  File "/home/user/bot-api-django/keyboards/default/orderkeyboards.py", line 6, in <module>
    data = requests.get(f'{ADDRES}category/').json()
           ^^^^^^^^^^^^^^^^^^^^^^^^^^^^^^^^^^
  File "/home/user/bot-api-django/.venv/lib/python3.11/site-packages/requests/api.py", line 73, in get
    return request("get", url, params=params, **kwargs)
           ^^^^^^^^^^^^^^^^^^^^^^^^^^^^^^^^^^^^^^^^^^^^
  File "/home/user/bot-api-django/.venv/lib/python3.11/site-packages/requests/api.py", line 59, in request
    return session.request(method=method, url=url, **kwargs)
           ^^^^^^^^^^^^^^^^^^^^^^^^^^^^^^^^^^^^^^^^^^^^^^^^^
  File "/home/user/bot-api-django/.venv/lib/python3.11/site-packages/requests/sessions.py", line 589, in request
    resp = self.send(prep, **send_kwargs)
           ^^^^^^^^^^^^^^^^^^^^^^^^^^^^^^
  File "/home/user/bot-api-django/.venv/lib/python3.11/site-packages/requests/sessions.py", line 703, in send
    r = adapter.send(request, **kwargs)
        ^^^^^^^^^^^^^^^^^^^^^^^^^^^^^^^
  File "/home/user/bot-api-django/.venv/lib/python3.11/site-packages/requests/adapters.py", line 700, in send
    raise ConnectionError(e, request=request)
requests.exceptions.ConnectionError: HTTPConnectionPool(host='127.0.0.1', port=8000): Max retries exceeded with url: /category/ (Caused by NewConnectionError('<urllib3.connection.HTTPConnection object at 0x7818a6287910>: Failed to establish a new connection: [Errno 111] Connection refused'))
executor.py [LINE:347] #INFO     [2024-07-19 17:13:51,615]  Bot: test fast food [@menu_fastfoood_bot]
notify_admins.py [LINE:28] #ERROR    [2024-07-19 17:13:52,864]  Chat not found
Traceback (most recent call last):
  File "/home/user/bot-api-django/utils/notify_admins.py", line 21, in on_startup_notify
    await dp.bot.send_message(user['tg_id'], "Bot qayta ishga tushdi iltimos /start ni "
  File "/home/user/bot-api-django/.venv/lib/python3.11/site-packages/aiogram/bot/bot.py", line 218, in send_message
    result = await self.request(api.Methods.SEND_MESSAGE, payload)
             ^^^^^^^^^^^^^^^^^^^^^^^^^^^^^^^^^^^^^^^^^^^^^^^^^^^^^
  File "/home/user/bot-api-django/.venv/lib/python3.11/site-packages/aiogram/bot/base.py", line 193, in request
    return await api.make_request(self.session, self.__token, method, data, files,
           ^^^^^^^^^^^^^^^^^^^^^^^^^^^^^^^^^^^^^^^^^^^^^^^^^^^^^^^^^^^^^^^^^^^^^^^
  File "/home/user/bot-api-django/.venv/lib/python3.11/site-packages/aiogram/bot/api.py", line 104, in make_request
    return check_result(method, response.content_type, response.status, await response.text())
           ^^^^^^^^^^^^^^^^^^^^^^^^^^^^^^^^^^^^^^^^^^^^^^^^^^^^^^^^^^^^^^^^^^^^^^^^^^^^^^^^^^^
  File "/home/user/bot-api-django/.venv/lib/python3.11/site-packages/aiogram/bot/api.py", line 78, in check_result
    exceptions.BadRequest.detect(description)
  File "/home/user/bot-api-django/.venv/lib/python3.11/site-packages/aiogram/utils/exceptions.py", line 136, in detect
    raise err(cls.text or description)
aiogram.utils.exceptions.ChatNotFound: Chat not found
dispatcher.py [LINE:269] #INFO     [2024-07-19 17:13:52,867]  Start polling.
error_handler.py [LINE:58] #ERROR    [2024-07-19 17:15:16,963]  Update: {"update_id":171896992,"message":{"message_id":247,"from":{"id":874354497,"is_bot":false,"first_name":"Abdulaziz","last_name":"Komilov | SWE","username":"abdulaziz9963","language_code":"en"},"chat":{"id":874354497,"first_name":"Abdulaziz","last_name":"Komilov | SWE","username":"abdulaziz9963","type":"private"},"date":1721409316,"text":"ðŸ›’ Korzina"}} 
HTTPConnectionPool(host='127.0.0.1', port=8000): Max retries exceeded with url: /korzina/list/874354497 (Caused by NewConnectionError('<urllib3.connection.HTTPConnection object at 0x7e6d41a24f90>: Failed to establish a new connection: [Errno 111] Connection refused'))
Traceback (most recent call last):
  File "/home/user/bot-api-django/.venv/lib/python3.11/site-packages/urllib3/connection.py", line 196, in _new_conn
    sock = connection.create_connection(
           ^^^^^^^^^^^^^^^^^^^^^^^^^^^^^
  File "/home/user/bot-api-django/.venv/lib/python3.11/site-packages/urllib3/util/connection.py", line 85, in create_connection
    raise err
  File "/home/user/bot-api-django/.venv/lib/python3.11/site-packages/urllib3/util/connection.py", line 73, in create_connection
    sock.connect(sa)
ConnectionRefusedError: [Errno 111] Connection refused

The above exception was the direct cause of the following exception:

Traceback (most recent call last):
  File "/home/user/bot-api-django/.venv/lib/python3.11/site-packages/urllib3/connectionpool.py", line 789, in urlopen
    response = self._make_request(
               ^^^^^^^^^^^^^^^^^^^
  File "/home/user/bot-api-django/.venv/lib/python3.11/site-packages/urllib3/connectionpool.py", line 495, in _make_request
    conn.request(
  File "/home/user/bot-api-django/.venv/lib/python3.11/site-packages/urllib3/connection.py", line 398, in request
    self.endheaders()
  File "/usr/lib/python3.11/http/client.py", line 1293, in endheaders
    self._send_output(message_body, encode_chunked=encode_chunked)
  File "/usr/lib/python3.11/http/client.py", line 1052, in _send_output
    self.send(msg)
  File "/usr/lib/python3.11/http/client.py", line 990, in send
    self.connect()
  File "/home/user/bot-api-django/.venv/lib/python3.11/site-packages/urllib3/connection.py", line 236, in connect
    self.sock = self._new_conn()
                ^^^^^^^^^^^^^^^^
  File "/home/user/bot-api-django/.venv/lib/python3.11/site-packages/urllib3/connection.py", line 211, in _new_conn
    raise NewConnectionError(
urllib3.exceptions.NewConnectionError: <urllib3.connection.HTTPConnection object at 0x7e6d41a24f90>: Failed to establish a new connection: [Errno 111] Connection refused

The above exception was the direct cause of the following exception:

Traceback (most recent call last):
  File "/home/user/bot-api-django/.venv/lib/python3.11/site-packages/requests/adapters.py", line 667, in send
    resp = conn.urlopen(
           ^^^^^^^^^^^^^
  File "/home/user/bot-api-django/.venv/lib/python3.11/site-packages/urllib3/connectionpool.py", line 843, in urlopen
    retries = retries.increment(
              ^^^^^^^^^^^^^^^^^^
  File "/home/user/bot-api-django/.venv/lib/python3.11/site-packages/urllib3/util/retry.py", line 519, in increment
    raise MaxRetryError(_pool, url, reason) from reason  # type: ignore[arg-type]
    ^^^^^^^^^^^^^^^^^^^^^^^^^^^^^^^^^^^^^^^^^^^^^^^^^^^
urllib3.exceptions.MaxRetryError: HTTPConnectionPool(host='127.0.0.1', port=8000): Max retries exceeded with url: /korzina/list/874354497 (Caused by NewConnectionError('<urllib3.connection.HTTPConnection object at 0x7e6d41a24f90>: Failed to establish a new connection: [Errno 111] Connection refused'))

During handling of the above exception, another exception occurred:

Traceback (most recent call last):
  File "/home/user/bot-api-django/.venv/lib/python3.11/site-packages/aiogram/dispatcher/dispatcher.py", line 199, in process_update
    return await self.message_handlers.notify(update.message)
           ^^^^^^^^^^^^^^^^^^^^^^^^^^^^^^^^^^^^^^^^^^^^^^^^^^
  File "/home/user/bot-api-django/.venv/lib/python3.11/site-packages/aiogram/dispatcher/handler.py", line 117, in notify
    response = await handler_obj.handler(*args, **partial_data)
               ^^^^^^^^^^^^^^^^^^^^^^^^^^^^^^^^^^^^^^^^^^^^^^^^
  File "/home/user/bot-api-django/handlers/users/start.py", line 189, in show_menu6
    data = requests.get(f'{ADDRES}korzina/list/{message.from_user.id}').json()
           ^^^^^^^^^^^^^^^^^^^^^^^^^^^^^^^^^^^^^^^^^^^^^^^^^^^^^^^^^^^^
  File "/home/user/bot-api-django/.venv/lib/python3.11/site-packages/requests/api.py", line 73, in get
    return request("get", url, params=params, **kwargs)
           ^^^^^^^^^^^^^^^^^^^^^^^^^^^^^^^^^^^^^^^^^^^^
  File "/home/user/bot-api-django/.venv/lib/python3.11/site-packages/requests/api.py", line 59, in request
    return session.request(method=method, url=url, **kwargs)
           ^^^^^^^^^^^^^^^^^^^^^^^^^^^^^^^^^^^^^^^^^^^^^^^^^
  File "/home/user/bot-api-django/.venv/lib/python3.11/site-packages/requests/sessions.py", line 589, in request
    resp = self.send(prep, **send_kwargs)
           ^^^^^^^^^^^^^^^^^^^^^^^^^^^^^^
  File "/home/user/bot-api-django/.venv/lib/python3.11/site-packages/requests/sessions.py", line 703, in send
    r = adapter.send(request, **kwargs)
        ^^^^^^^^^^^^^^^^^^^^^^^^^^^^^^^
  File "/home/user/bot-api-django/.venv/lib/python3.11/site-packages/requests/adapters.py", line 700, in send
    raise ConnectionError(e, request=request)
requests.exceptions.ConnectionError: HTTPConnectionPool(host='127.0.0.1', port=8000): Max retries exceeded with url: /korzina/list/874354497 (Caused by NewConnectionError('<urllib3.connection.HTTPConnection object at 0x7e6d41a24f90>: Failed to establish a new connection: [Errno 111] Connection refused'))
base_events.py [LINE:1785] #ERROR    [2024-07-19 17:15:16,969]  Task exception was never retrieved
future: <Task finished name='Task-55' coro=<Dispatcher._process_polling_updates() done, defined at /home/user/bot-api-django/.venv/lib/python3.11/site-packages/aiogram/dispatcher/dispatcher.py:313> exception=ConnectionError(MaxRetryError("HTTPConnectionPool(host='127.0.0.1', port=8000): Max retries exceeded with url: /korzina/list/874354497 (Caused by NewConnectionError('<urllib3.connection.HTTPConnection object at 0x7e6d41a24f90>: Failed to establish a new connection: [Errno 111] Connection refused'))"))>
Traceback (most recent call last):
  File "/home/user/bot-api-django/.venv/lib/python3.11/site-packages/urllib3/connection.py", line 196, in _new_conn
    sock = connection.create_connection(
           ^^^^^^^^^^^^^^^^^^^^^^^^^^^^^
  File "/home/user/bot-api-django/.venv/lib/python3.11/site-packages/urllib3/util/connection.py", line 85, in create_connection
    raise err
  File "/home/user/bot-api-django/.venv/lib/python3.11/site-packages/urllib3/util/connection.py", line 73, in create_connection
    sock.connect(sa)
ConnectionRefusedError: [Errno 111] Connection refused

The above exception was the direct cause of the following exception:

Traceback (most recent call last):
  File "/home/user/bot-api-django/.venv/lib/python3.11/site-packages/urllib3/connectionpool.py", line 789, in urlopen
    response = self._make_request(
               ^^^^^^^^^^^^^^^^^^^
  File "/home/user/bot-api-django/.venv/lib/python3.11/site-packages/urllib3/connectionpool.py", line 495, in _make_request
    conn.request(
  File "/home/user/bot-api-django/.venv/lib/python3.11/site-packages/urllib3/connection.py", line 398, in request
    self.endheaders()
  File "/usr/lib/python3.11/http/client.py", line 1293, in endheaders
    self._send_output(message_body, encode_chunked=encode_chunked)
  File "/usr/lib/python3.11/http/client.py", line 1052, in _send_output
    self.send(msg)
  File "/usr/lib/python3.11/http/client.py", line 990, in send
    self.connect()
  File "/home/user/bot-api-django/.venv/lib/python3.11/site-packages/urllib3/connection.py", line 236, in connect
    self.sock = self._new_conn()
                ^^^^^^^^^^^^^^^^
  File "/home/user/bot-api-django/.venv/lib/python3.11/site-packages/urllib3/connection.py", line 211, in _new_conn
    raise NewConnectionError(
urllib3.exceptions.NewConnectionError: <urllib3.connection.HTTPConnection object at 0x7e6d41a24f90>: Failed to establish a new connection: [Errno 111] Connection refused

The above exception was the direct cause of the following exception:

Traceback (most recent call last):
  File "/home/user/bot-api-django/.venv/lib/python3.11/site-packages/requests/adapters.py", line 667, in send
    resp = conn.urlopen(
           ^^^^^^^^^^^^^
  File "/home/user/bot-api-django/.venv/lib/python3.11/site-packages/urllib3/connectionpool.py", line 843, in urlopen
    retries = retries.increment(
              ^^^^^^^^^^^^^^^^^^
  File "/home/user/bot-api-django/.venv/lib/python3.11/site-packages/urllib3/util/retry.py", line 519, in increment
    raise MaxRetryError(_pool, url, reason) from reason  # type: ignore[arg-type]
    ^^^^^^^^^^^^^^^^^^^^^^^^^^^^^^^^^^^^^^^^^^^^^^^^^^^
urllib3.exceptions.MaxRetryError: HTTPConnectionPool(host='127.0.0.1', port=8000): Max retries exceeded with url: /korzina/list/874354497 (Caused by NewConnectionError('<urllib3.connection.HTTPConnection object at 0x7e6d41a24f90>: Failed to establish a new connection: [Errno 111] Connection refused'))

During handling of the above exception, another exception occurred:

Traceback (most recent call last):
  File "/home/user/bot-api-django/.venv/lib/python3.11/site-packages/aiogram/dispatcher/dispatcher.py", line 321, in _process_polling_updates
    for responses in itertools.chain.from_iterable(await self.process_updates(updates, fast)):
                                                   ^^^^^^^^^^^^^^^^^^^^^^^^^^^^^^^^^^^^^^^^^
  File "/home/user/bot-api-django/.venv/lib/python3.11/site-packages/aiogram/dispatcher/dispatcher.py", line 179, in process_updates
    return await asyncio.gather(*tasks)
           ^^^^^^^^^^^^^^^^^^^^^^^^^^^^
  File "/home/user/bot-api-django/.venv/lib/python3.11/site-packages/aiogram/dispatcher/handler.py", line 117, in notify
    response = await handler_obj.handler(*args, **partial_data)
               ^^^^^^^^^^^^^^^^^^^^^^^^^^^^^^^^^^^^^^^^^^^^^^^^
  File "/home/user/bot-api-django/.venv/lib/python3.11/site-packages/aiogram/dispatcher/dispatcher.py", line 199, in process_update
    return await self.message_handlers.notify(update.message)
           ^^^^^^^^^^^^^^^^^^^^^^^^^^^^^^^^^^^^^^^^^^^^^^^^^^
  File "/home/user/bot-api-django/.venv/lib/python3.11/site-packages/aiogram/dispatcher/handler.py", line 117, in notify
    response = await handler_obj.handler(*args, **partial_data)
               ^^^^^^^^^^^^^^^^^^^^^^^^^^^^^^^^^^^^^^^^^^^^^^^^
  File "/home/user/bot-api-django/handlers/users/start.py", line 189, in show_menu6
    data = requests.get(f'{ADDRES}korzina/list/{message.from_user.id}').json()
           ^^^^^^^^^^^^^^^^^^^^^^^^^^^^^^^^^^^^^^^^^^^^^^^^^^^^^^^^^^^^
  File "/home/user/bot-api-django/.venv/lib/python3.11/site-packages/requests/api.py", line 73, in get
    return request("get", url, params=params, **kwargs)
           ^^^^^^^^^^^^^^^^^^^^^^^^^^^^^^^^^^^^^^^^^^^^
  File "/home/user/bot-api-django/.venv/lib/python3.11/site-packages/requests/api.py", line 59, in request
    return session.request(method=method, url=url, **kwargs)
           ^^^^^^^^^^^^^^^^^^^^^^^^^^^^^^^^^^^^^^^^^^^^^^^^^
  File "/home/user/bot-api-django/.venv/lib/python3.11/site-packages/requests/sessions.py", line 589, in request
    resp = self.send(prep, **send_kwargs)
           ^^^^^^^^^^^^^^^^^^^^^^^^^^^^^^
  File "/home/user/bot-api-django/.venv/lib/python3.11/site-packages/requests/sessions.py", line 703, in send
    r = adapter.send(request, **kwargs)
        ^^^^^^^^^^^^^^^^^^^^^^^^^^^^^^^
  File "/home/user/bot-api-django/.venv/lib/python3.11/site-packages/requests/adapters.py", line 700, in send
    raise ConnectionError(e, request=request)
requests.exceptions.ConnectionError: HTTPConnectionPool(host='127.0.0.1', port=8000): Max retries exceeded with url: /korzina/list/874354497 (Caused by NewConnectionError('<urllib3.connection.HTTPConnection object at 0x7e6d41a24f90>: Failed to establish a new connection: [Errno 111] Connection refused'))
